{"error": "Traceback (most recent call last):\n  File \"/cs/+/usr/ofer1992/ants/tools/sandbox.py\", line 383, in start\n    cwd=working_directory)\n  File \"/usr/lib/python3.5/subprocess.py\", line 676, in __init__\n    restore_signals, start_new_session)\n  File \"/usr/lib/python3.5/subprocess.py\", line 1282, in _execute_child\n    raise child_exception_type(errno_num, err_msg)\nFileNotFoundError: [Errno 2] No such file or directory: '$1'\n\nDuring handling of the above exception, another exception occurred:\n\nTraceback (most recent call last):\n  File \"/cs/+/usr/ofer1992/ants/tools/engine.py\", line 93, in run_game\n    sandbox.start(bot_cmd)\n  File \"/cs/+/usr/ofer1992/ants/tools/sandbox.py\", line 385, in start\n    raise SandboxError('Failed to start {0}'.format(shell_command))\nsandbox.SandboxError: Failed to start ['$1']\n", "playernames": [null, "TestBot.py"]}